<?xml version="1.0"?>
<robot name="ur5_rg2">

  <!-- Arm Links -->
  <link name="base_link">
    <visual name="base_link_visual">
      <geometry>
        <mesh filename="package://robot_description/meshes/visual/ur5/base.dae"/>
      </geometry>
    </visual>
    <collision name="base_link_collision">
      <geometry>
        <mesh filename="package://robot_description/meshes/collision/ur5/base.stl"/>
      </geometry>
    </collision>
    <inertial>
      <mass value="10"/>
      <inertia ixx="0.4" ixy="0.0" ixz="0.0" iyy="0.4" iyz="0.0" izz="0.2"/>
    </inertial>

  </link>

  <link name="shoulder_link">
    <visual name="shoulder_link_visual">
      <geometry>
        <mesh filename="package://robot_description/meshes/visual/ur5/shoulder.dae"/>
      </geometry>
    </visual>
    <collision name="shoulder_link_collision">
      <geometry>
        <mesh filename="package://robot_description/meshes/collision/ur5/shoulder.stl"/>
      </geometry>
    </collision>
    <inertial>
      <mass value="10"/>
      <inertia ixx="0.4" ixy="0.0" ixz="0.0" iyy="0.4" iyz="0.0" izz="0.2"/>
    </inertial>

  </link>

  <link name="upper_arm_link">
    <visual name="upper_arm_link_visual">
      <geometry>
        <mesh filename="package://robot_description/meshes/visual/ur5/upperarm.dae"/>
      </geometry>
    </visual>
    <collision name="upper_arm_link_collision">
      <geometry>
        <mesh filename="package://robot_description/meshes/collision/ur5/upperarm.stl"/>
      </geometry>
    </collision>
    <inertial>
      <mass value="10"/>
      <inertia ixx="0.4" ixy="0.0" ixz="0.0" iyy="0.4" iyz="0.0" izz="0.2"/>
    </inertial>

  </link>

  <link name="forearm_link">
    <visual name="forearm_link_visual">
      <geometry>
        <mesh filename="package://robot_description/meshes/visual/ur5/forearm.dae"/>
      </geometry>
    </visual>
    <collision name="forearm_link_collision">
      <geometry>
        <mesh filename="package://robot_description/meshes/collision/ur5/forearm.stl"/>
      </geometry>
    </collision>
    <inertial>
      <mass value="10"/>
      <inertia ixx="0.4" ixy="0.0" ixz="0.0" iyy="0.4" iyz="0.0" izz="0.2"/>
    </inertial>

  </link>

  <link name="wrist_1_link">
    <visual name="wrist_1_link_visual">
      <geometry>
        <mesh filename="package://robot_description/meshes/visual/ur5/wrist1.dae"/>
      </geometry>
    </visual>
    <collision name="wrist_1_link_collision">
      <geometry>
        <mesh filename="package://robot_description/meshes/collision/ur5/wrist1.stl"/>
      </geometry>
    </collision>
    <inertial>
      <mass value="10"/>
      <inertia ixx="0.4" ixy="0.0" ixz="0.0" iyy="0.4" iyz="0.0" izz="0.2"/>
    </inertial>

  </link>

  <link name="wrist_2_link">
    <visual name="wrist_2_link_visual">
      <geometry>
        <mesh filename="package://robot_description/meshes/visual/ur5/wrist2.dae"/>
      </geometry>
    </visual>
    <collision name="wrist_2_link_collision">
      <geometry>
        <mesh filename="package://robot_description/meshes/collision/ur5/wrist2.stl"/>
      </geometry>
    </collision>
    <inertial>
      <mass value="10"/>
      <inertia ixx="0.4" ixy="0.0" ixz="0.0" iyy="0.4" iyz="0.0" izz="0.2"/>
    </inertial>

  </link>

  <link name="wrist_3_link">
    <visual name="wrist_3_link_visual">
      <geometry>
        <mesh filename="package://robot_description/meshes/visual/ur5/wrist3.dae"/>
      </geometry>
    </visual>
    <collision name="wrist_3_link_collision">
      <geometry>
        <mesh filename="package://robot_description/meshes/collision/ur5/wrist3.stl"/>
      </geometry>
    </collision>
    <inertial>
      <mass value="10"/>
      <inertia ixx="0.4" ixy="0.0" ixz="0.0" iyy="0.4" iyz="0.0" izz="0.2"/>
    </inertial>

  </link>


  <!-- Arm Joints -->
  <joint name="shoulder_pan_joint" type="revolute">
    <parent link="base_link"/>
    <child link="shoulder_link"/>
    <origin xyz="0 0 0.089159" rpy="0 0 0"/>
    <axis xyz="0 0 1"/>
    <limit lower="-6.28319" upper="6.28319" effort="150.0" velocity="3.15"/>
  </joint>

  <joint name="shoulder_lift_joint" type="revolute">
    <parent link="shoulder_link"/>
    <child link="upper_arm_link"/>
    <origin xyz="0 0.13585 0" rpy="0 0 0"/>
    <axis xyz="0 1 0"/>
    <limit lower="-6.28319" upper="6.28319" effort="150.0" velocity="3.15"/>
  </joint>

  <joint name="elbow_joint" type="revolute">
    <parent link="upper_arm_link"/>
    <child link="forearm_link"/>
    <origin xyz="0 -0.1197 0.425" rpy="0 0 0"/>
    <axis xyz="0 1 0"/>
    <limit lower="-6.28319" upper="6.28319" effort="150.0" velocity="3.15"/>
  </joint>

  <joint name="wrist_1_joint" type="revolute">
    <parent link="forearm_link"/>
    <child link="wrist_1_link"/>
    <origin xyz="0 0 0.39225" rpy="0 0 0"/>
    <axis xyz="0 1 0"/>
    <limit lower="-6.28319" upper="6.28319" effort="28.0" velocity="3.2"/>
  </joint>

  <joint name="wrist_2_joint" type="revolute">
    <parent link="wrist_1_link"/>
    <child link="wrist_2_link"/>
    <origin xyz="0 0.093 0" rpy="0 0 0"/>
    <axis xyz="0 0 1"/>
    <limit lower="-6.28319" upper="6.28319" effort="28.0" velocity="3.2"/>
  </joint>

  <joint name="wrist_3_joint" type="revolute">
    <parent link="wrist_2_link"/>
    <child link="wrist_3_link"/>
    <origin xyz="0 0 0.09465" rpy="0 0 0"/>
    <axis xyz="0 1 0"/>
    <limit lower="-6.28319" upper="6.28319" effort="28.0" velocity="3.2"/>
  </joint>

</robot>
