<?xml version="1.0"?>
<robot name="ur5_rg2">

  <!-- Arm Links -->
  <link name="base_link">
    <visual name="base_link_visual">
      <geometry>
        <mesh filename="package:///meshes/visual/ur5/base.dae"/>
      </geometry>
    </visual>
    <collision name="base_link_collision">
      <geometry>
        <mesh filename="package:///meshes/collision/ur5/base.stl"/>
      </geometry>
    </collision>
  </link>

  <link name="shoulder_link">
    <visual name="shoulder_link_visual">
      <geometry>
        <mesh filename="package:///meshes/visual/ur5/shoulder.dae"/>
      </geometry>
    </visual>
    <collision name="shoulder_link_collision">
      <geometry>
        <mesh filename="package:///meshes/collision/ur5/shoulder.stl"/>
      </geometry>
    </collision>
    <inertial>
      <origin rpy="0 0 0" xyz="-0.025566 -2.87883e-05 0.057332"/>
      <mass value="2.814271300104062"/>
      <inertia ixx="0.0075390636364814695" ixy="-1.5053124574783335e-05" ixz="-0.0012144328835738973" iyy="0.010508017427382959" iyz="1.0434803501032979e-05" izz="0.009864933638708275"/>
    </inertial>
  </link>

  <link name="upper_arm_link">
    <visual name="upper_arm_link_visual">
      <geometry>
        <mesh filename="package:///meshes/visual/ur5/upperarm.dae"/>
      </geometry>
    </visual>
    <collision name="upper_arm_link_collision">
      <geometry>
        <mesh filename="package:///meshes/collision/ur5/upperarm.stl"/>
      </geometry>
    </collision>
  </link>

  <link name="forearm_link">
    <visual name="forearm_link_visual">
      <geometry>
        <mesh filename="package:///meshes/visual/ur5/forearm.dae"/>
      </geometry>
    </visual>
    <collision name="forearm_link_collision">
      <geometry>
        <mesh filename="package:///meshes/collision/ur5/forearm.stl"/>
      </geometry>
    </collision>
  </link>

  <link name="wrist_1_link">
    <visual name="wrist_1_link_visual">
      <geometry>
        <mesh filename="package:///meshes/visual/ur5/wrist1.dae"/>
      </geometry>
    </visual>
    <collision name="wrist_1_link_collision">
      <geometry>
        <mesh filename="package:///meshes/collision/ur5/wrist1.stl"/>
      </geometry>
    </collision>
  </link>

  <link name="wrist_2_link">
    <visual name="wrist_2_link_visual">
      <geometry>
        <mesh filename="package:///meshes/visual/ur5/wrist2.dae"/>
      </geometry>
    </visual>
    <collision name="wrist_2_link_collision">
      <geometry>
        <mesh filename="package:///meshes/collision/ur5/wrist2.stl"/>
      </geometry>
    </collision>
  </link>

  <link name="wrist_3_link">
    <visual name="wrist_3_link_visual">
      <geometry>
        <mesh filename="package:///meshes/visual/ur5/wrist3.dae"/>
      </geometry>
    </visual>
    <collision name="wrist_3_link_collision">
      <geometry>
        <mesh filename="package:///meshes/collision/ur5/wrist3.stl"/>
      </geometry>
    </collision>
  </link>


  <!-- Arm Joints -->
  <joint name="shoulder_pan_joint" type="revolute">
    <parent link="base_link"/>
    <child link="shoulder_link"/>
    <origin xyz="0 0 0.089159" rpy="0 0 0"/>
    <axis xyz="0 0 1"/>
    <limit lower="-6.28319" upper="6.28319" effort="150.0" velocity="3.15"/>
  </joint>

  <joint name="shoulder_lift_joint" type="revolute">
    <parent link="shoulder_link"/>
    <child link="upper_arm_link"/>
    <origin xyz="0 0.13585 0" rpy="0 0 0"/>
    <axis xyz="0 1 0"/>
    <limit lower="-6.28319" upper="6.28319" effort="150.0" velocity="3.15"/>
  </joint>

  <joint name="elbow_joint" type="revolute">
    <parent link="upper_arm_link"/>
    <child link="forearm_link"/>
    <origin xyz="0 -0.1197 0.425" rpy="0 0 0"/>
    <axis xyz="0 1 0"/>
    <limit lower="-6.28319" upper="6.28319" effort="150.0" velocity="3.15"/>
  </joint>

  <joint name="wrist_1_joint" type="revolute">
    <parent link="forearm_link"/>
    <child link="wrist_1_link"/>
    <origin xyz="0 0 0.39225" rpy="0 0 0"/>
    <axis xyz="0 1 0"/>
    <limit lower="-6.28319" upper="6.28319" effort="28.0" velocity="3.2"/>
  </joint>

  <joint name="wrist_2_joint" type="revolute">
    <parent link="wrist_1_link"/>
    <child link="wrist_2_link"/>
    <origin xyz="0 0.093 0" rpy="0 0 0"/>
    <axis xyz="0 0 1"/>
    <limit lower="-6.28319" upper="6.28319" effort="28.0" velocity="3.2"/>
  </joint>

  <joint name="wrist_3_joint" type="revolute">
    <parent link="wrist_2_link"/>
    <child link="wrist_3_link"/>
    <origin xyz="0 0 0.09465" rpy="0 0 0"/>
    <axis xyz="0 1 0"/>
    <limit lower="-6.28319" upper="6.28319" effort="28.0" velocity="3.2"/>
  </joint>
  <ros2_control name="ur_arm_system" type="system">
    <hardware>
      <plugin>ign_ros2_control/IgnitionSystem</plugin>
    </hardware>
    <joint name="shoulder_pan_joint">
      <param name="initial_position">0.0</param>
      <command_interface name="effort"/>
      <state_interface name="position"/>
      <state_interface name="velocity"/>
      <state_interface name="effort"/>
    </joint>
    <joint name="shoulder_lift_joint">
      <param name="initial_position">-0.7853981633974483</param>
      <command_interface name="effort"/>
      <state_interface name="position"/>
      <state_interface name="velocity"/>
      <state_interface name="effort"/>
    </joint>
    <joint name="elbow_joint">
      <param name="initial_position">0.0</param>
      <command_interface name="effort"/>
      <state_interface name="position"/>
      <state_interface name="velocity"/>
      <state_interface name="effort"/>
    </joint>
    <joint name="wrist_1_joint">
      <param name="initial_position">-2.356194490192345</param>
      <command_interface name="effort"/>
      <state_interface name="position"/>
      <state_interface name="velocity"/>
      <state_interface name="effort"/>
    </joint>
    <joint name="wrist_2_joint">
      <param name="initial_position">0.0</param>
      <command_interface name="effort"/>
      <state_interface name="position"/>
      <state_interface name="velocity"/>
      <state_interface name="effort"/>
    </joint>
    <joint name="wrist_3_joint">
      <param name="initial_position">1.5707963267948966</param>
      <command_interface name="effort"/>
      <state_interface name="position"/>
      <state_interface name="velocity"/>
      <state_interface name="effort"/>
    </joint>
  </ros2_control>
</robot>
